<?xml version="1.0" encoding="utf-8"?>
<robot xmlns:xacro="http://www.ros.org/wiki/xacro" name="hand">
  <!-- safety_distance: Minimum safety distance in [m] by which the collision volumes are expanded and which is enforced during robot motions -->
  <xacro:macro name="hand" params="connected_to:='' ns:='' rpy:='0 0 0' xyz:='0 0 0' safety_distance:=0">
    <xacro:unless value="${connected_to == ''}">
      <joint name="${ns}_hand_joint" type="fixed">
        <parent link="${connected_to}"/>
        <child link="${ns}_hand"/>
        <origin xyz="${xyz}" rpy="${rpy}"/>
      </joint>
    </xacro:unless>
    <link name="${ns}_hand">
      <visual>
        <geometry>
          <mesh filename="package://franka_description/meshes/visual/hand.dae"/>
        </geometry>
      </visual>
      <collision>
        <geometry>
          <mesh filename="package://franka_description/meshes/collision/hand.stl"/>
        </geometry>
      </collision>

      <!-- for simulation -->
      <inertial>
        <origin xyz="0 0 0" rpy="0 0 0" />
        <mass value="0.68" />
        <inertia ixx="0.1" ixy="0.0" ixz="0.0" iyy="0.1" iyz="0.0" izz="0.1" />
      </inertial>
      <!-- end for simulation -->
    </link>
    <link name="${ns}_leftfinger">
      <!-- <visual>
        <geometry>
          <mesh filename="package://franka_description/meshes/visual/finger.dae"/>
        </geometry>
      </visual>
      <collision>
        <geometry>
          <mesh filename="package://franka_description/meshes/collision/finger.stl"/>
        </geometry>
      </collision> -->

      <!-- contact infomatioin based on https://answers.gazebosim.org//question/9371/finger-contact-erp-cfm-kp-and-kd/-->
      <visual>
        <origin xyz="0 0 0.03" rpy="0 0 0" />
        <geometry>
          <box size="0.02 0.02 0.06"/>
        </geometry>
      </visual>
      <collision>
        <origin xyz="0 0 0.03" rpy="0 0 0" />
        <max_contacts>10</max_contacts>
        <geometry>
          <box size="0.02 0.02 0.06"/>
        </geometry>
        <surface>
          <friction>
            <ode>
              <mu>0.8</mu>
              <mu2>0.8</mu2>
            </ode>
          </friction>
          <bounce>
            <restitution_coefficient>0.01</restitution_coefficient>
            <threshold>0.01</threshold>
          </bounce>
          <contact>
            <ode>
              <max_vel>0.1</max_vel>
              <soft_cfm>0.8</soft_cfm>
              <soft_erp>0.8</soft_erp>
              <kd>2500</kd>
              <kp>10</kp>
              <min_depth>0.001</min_depth>
            </ode>
          </contact>
        </surface>
      </collision>

      <!-- for simulation -->
      <inertial>
        <origin xyz="0 0 0.03" rpy="0 0 0" />
        <mass value="0.68" />
        <inertia ixx="0.1" ixy="0.0" ixz="0.0" iyy="0.1" iyz="0.0" izz="0.1" />
      </inertial>
      <!-- end for simulation -->
    </link>
    <link name="${ns}_rightfinger">
      <!-- <visual>
        <origin xyz="0 0 0" rpy="0 0 ${pi}"/>
        <geometry>
          <mesh filename="package://franka_description/meshes/visual/finger.dae"/>
        </geometry>
      </visual>
      <collision>
        <origin xyz="0 0 0" rpy="0 0 ${pi}"/>
        <geometry>
          <mesh filename="package://franka_description/meshes/collision/finger.stl"/>
        </geometry>
      </collision> -->
      <visual>
        <origin xyz="0 0 0.03" rpy="0 0 ${pi}"/>
        <geometry>
          <box size="0.02 0.02 0.06"/>
        </geometry>
      </visual>
      <collision>
        <origin xyz="0 0 0.03" rpy="0 0 ${pi}"/>
        <max_contacts>10</max_contacts>
        <geometry>
          <box size="0.02 0.02 0.06"/>
        </geometry>
        <surface>
          <friction>
            <ode>
              <mu>0.8</mu>
              <mu2>0.8</mu2>
            </ode>
          </friction>
          <bounce>
            <restitution_coefficient>0.01</restitution_coefficient>
            <threshold>0.01</threshold>
          </bounce>
          <contact>
            <ode>
              <max_vel>0.1</max_vel>
              <soft_cfm>0.8</soft_cfm>
              <soft_erp>0.8</soft_erp>
              <kd>2500</kd>
              <kp>10</kp>
              <min_depth>0.001</min_depth>
            </ode>
          </contact>
        </surface>
      </collision>

      <!-- for simulation -->
      <inertial>
        <origin xyz="0 0 0.03" rpy="0 0 ${pi}"/>
        <mass value="0.68" />
        <inertia ixx="0.1" ixy="0.0" ixz="0.0" iyy="0.1" iyz="0.0" izz="0.1" />
      </inertial>
      <!-- end for simulation -->
   </link>
    <joint name="${ns}_finger_joint1" type="prismatic">
      <parent link="${ns}_hand"/>
      <child link="${ns}_leftfinger"/>
      <origin xyz="0 0.018 0.0584" rpy="0 0 0"/>
      <axis xyz="0 1 0"/>
      <limit effort="20" lower="0.00" upper="0.04" velocity="0.2"/>
    </joint>
    <joint name="${ns}_finger_joint2" type="prismatic">
      <parent link="${ns}_hand"/>
      <child link="${ns}_rightfinger"/>
      <origin xyz="0 -0.018 0.0584" rpy="0 0 0"/>
      <axis xyz="0 -1 0"/>
      <limit effort="20" lower="0.00" upper="0.04" velocity="0.2"/>
      <!-- <mimic joint="${ns}_finger_joint1" /> -->
    </joint>
  </xacro:macro>
</robot>